Workbook

Sheet 01_設計書
A1: ゲームAI課題制作 設計シート
A3: 教科書のどの分野・技術を意識して設計したかを、実装前に言語化するためのシートです。
A5: 基本情報
A6: 氏名 | B6: かも | E6: 作品名 | F6: WINGS | G6: 主分野 | H6: 協調を作る
A7: 補助分野1 | B7: 認識を作る | C7: 補助分野2 | D7: 身体を作る | F7: 個人
A9: AIの設計
A10: AIの目的 （何者で、何を達成するAIか） | B10: タワーへ侵攻する敵群と、追従・防衛・攻撃の指示を遂行する味方部隊を制御する。認識→判断→移動・攻撃を分離し、全体リストにいるだけの敵を既知とは扱わない。 | C10: 見せたい知性 （どんな振る舞いに見せたいか） | D10: 敵はNavMeshで拠点へ進み、セル内の近傍回避と包囲位置の予約で一列への集中を抑える。味方は編隊間隔と命令の行動範囲を保ち、目視した敵から適した攻撃目標を選ぶ。見失った相手の現在位置は追わない。 | E10: 認識するもの （距離・視界・属性・音など） | F10: 視覚は距離・水平視野角・上下角・遮蔽物を約0.12秒ごとに判定。味方は120度、敵は110度。視認距離は味方25～55m、敵20～25m。胴・肩・頭の3点を調べ、射撃は別に銃口からの射線と武器射程を確認する。タワー位置とNavMeshは既知の任務・地図情報。音の推定は未採用。 | G10: 内部状態・記憶 （HP・警戒度・記憶・学習値など） | H10: 大命令は追従・防衛・攻撃を保持。追従は編隊位置へ戻り、リーダーから12mを超えたら帰還を優先。防衛はタワーから11mの範囲を維持。攻撃は目視した敵へ接近し、敵を知らなければ巡回。内部状態は警戒・帰還・追跡・位置調整・攻撃・捜索・装填。最終目撃位置は固定して3秒で忘れ、味方の報告は元の目撃時刻から1.5秒で失効。HP・弾数・射程・クールダウンも参照する。
A13: 判断方法 （FSM・Utility・Goal・ルール等） | B13: 大命令＋FSMで行動を切り替え、目視した候補の距離・拠点への脅威・味方の担当数を効用スコアで比較する。目標は0.65秒保持し、原則8点以上有利な候補へ切替。安全条件はルールで判定。GOAP、学習、先読みシミュレーションは今回は使用しない。 | C13: 行動 （巡回・追跡・逃走・休憩など） | D13: 敵：拠点へ進行、目視した相手へ接近・包囲、射線・距離確認後に攻撃。味方：編隊追従、拠点警戒、巡回、目視目標の追跡、適正射程への位置調整、装填、状況に応じた固有能力。視界を失うと最終目撃地点を調べる。 | E13: 世界・身体の制約 （見えない・届かない・遅い等） | F13: 視界外の現在位置・HPは判断に使わない。記憶・報告だけでは射撃しない。頭が見えても銃口が隠れていれば位置を変える。タカのULTは壁の遮蔽だけ例外で、距離・視野角は維持。物理的な近傍回避は敵の発見情報にはしない。移動先は命令の範囲とNavMeshに制約される。 | G13: 確認方法 （Gizmos・画面表示・ログ等） | H13: F1で味方の命令・状態・判断理由・目視数・射撃許可・経路を表示。UnityでAIBodyを選択すると視野扇形、目視線、最終目撃地点をGizmos表示。味方の状態遷移はログに記録。自動検証で背後・距離外・遮蔽・低い壁・記憶の固定と失効・報告の失効・行動範囲・NavMesh迂回・包囲分担を確認する。
A16: 分野別の採用状況（「02_技術選択」の採用数を自動集計）
A17: 分野 | B17: 採用数 | C17: 主/補助の意識 | D17: 制作での役割 | F17: 提出前チェック
A18: ゲームAIの作り方 | B18: =COUNTIFS('02_技術選択'!$A:$A,"採用",'02_技術選択'!$C:$C,A18) -> 0 | C18: =IF($H$6=A18,"主分野",IF(OR($B$7=A18,$D$7=A18),"補助分野","")) | F18: 主分野が選ばれている | G18: =IF($H$6<>"","OK","未入力") -> OK
A19: 認識を作る | B19: =COUNTIFS('02_技術選択'!$A:$A,"採用",'02_技術選択'!$C:$C,A19) -> 3 | C19: =IF($H$6=A19,"主分野",IF(OR($B$7=A19,$D$7=A19),"補助分野","")) -> 補助分野 | F19: 主分野で技術を1つ以上採用 | G19: =IF(COUNTIFS('02_技術選択'!$A:$A,"採用",'02_技術選択'!$C:$C,$H$6)>=1,"OK","要確認") -> OK
A20: 身体を作る | B20: =COUNTIFS('02_技術選択'!$A:$A,"採用",'02_技術選択'!$C:$C,A20) -> 3 | C20: =IF($H$6=A20,"主分野",IF(OR($B$7=A20,$D$7=A20),"補助分野","")) -> 補助分野 | F20: 認識するものを記述 | G20: =IF(LEN($F$10)>5,"OK","要確認") -> OK
A21: 学習を作る | B21: =COUNTIFS('02_技術選択'!$A:$A,"採用",'02_技術選択'!$C:$C,A21) -> 0 | C21: =IF($H$6=A21,"主分野",IF(OR($B$7=A21,$D$7=A21),"補助分野","")) | F21: 判断方法を記述 | G21: =IF(LEN($B$13)>3,"OK","要確認") -> OK
A22: 協調を作る | B22: =COUNTIFS('02_技術選択'!$A:$A,"採用",'02_技術選択'!$C:$C,A22) -> 5 | C22: =IF($H$6=A22,"主分野",IF(OR($B$7=A22,$D$7=A22),"補助分野","")) -> 主分野 | F22: 行動を記述 | G22: =IF(LEN($D$13)>3,"OK","要確認") -> OK
A23: 知能を作る | B23: =COUNTIFS('02_技術選択'!$A:$A,"採用",'02_技術選択'!$C:$C,A23) -> 4 | C23: =IF($H$6=A23,"主分野",IF(OR($B$7=A23,$D$7=A23),"補助分野","")) | F23: 確認方法を記述 | G23: =IF(LEN($H$13)>3,"OK","要確認") -> OK

Sheet 02_技術選択
A1: 教科書ロードマップから、制作で意識する技術・概念を選ぶ
A3: 「採用」にした項目は提出用まとめへ反映できます。最低でも主分野から1項目は採用し、F～I列に自分の実装方針を書いてください。
A5: 採用状況 | B5: 位置づけ | C5: 分野 | D5: 技術・概念 | E5: 章 | F5: 何のために使うか | G5: Unity上でどう実装するか | H5: 期待する挙動 | I5: どう確認するか | J5: 備考
A6: 未使用 | B6: 参考 | C6: ゲームAIの作り方 | D6: 知能と宇宙 | E6: 1章
A7: 未使用 | B7: 参考 | C7: ゲームAIの作り方 | D7: AIの歴史とゲームAIの歴史 | E7: 1章
A8: 未使用 | B8: 参考 | C8: ゲームAIの作り方 | D8: デジタルゲームの2つの進化 | E8: 1章
A9: 未使用 | B9: 参考 | C9: ゲームAIの作り方 | D9: 生きているということ | E9: 2章
A10: 未使用 | B10: 参考 | C10: ゲームAIの作り方 | D10: 現実感（リアリティ）を追求する | E10: 2章
A11: 未使用 | B11: 参考 | C11: ゲームAIの作り方 | D11: 現実を作る秩序 | E11: 3章
A12: 未使用 | B12: 参考 | C12: ゲームAIの作り方 | D12: デジタルゲームにおける人工知能 | E12: 2章
A13: 未使用 | B13: 参考 | C13: ゲームAIの作り方 | D13: ゲームにおいて知能を感じる | E13: 3章
A14: 未使用 | B14: 参考 | C14: ゲームAIの作り方 | D14: 3つのゲームAIでユーザー体験を作る | E14: 2章
A15: 未使用 | B15: 参考 | C15: ゲームAIの作り方 | D15: 人工知能の中心課題「フレーム」 | E15: 3章
A16: 未使用 | B16: 参考 | C16: 認識を作る | D16: メタ思考とメタ知識 | E16: 2章
A17: 採用 | B17: 補助 | C17: 認識を作る | D17: ブラックボード・アーキテクチャで世界を認識する | E17: 2章 | F17: センサーで得た事実を判断用の記録へ分離する。 | G17: VisionSensorのContactに目標ID、観測位置、目撃時刻、可視状態、情報源、信頼度を保存する。 | H17: 全体に存在する敵と、自分が知る敵を区別する。 | I17: 背後・壁裏にいる登録済みの敵を選ばない試験。 | J17: 本作の個体内認識記録として採用。
A18: 未使用 | B18: 参考 | C18: 認識を作る | D18: 人工知能はコンテキストを理解できるか | E18: 3章
A19: 未使用 | B19: 参考 | C19: 認識を作る | D19: 物・事・世界 | E19: 5章
A20: 未使用 | B20: 参考 | C20: 認識を作る | D20: 物語の力 | E20: 5章
A21: 採用 | B21: 補助 | C21: 認識を作る | D21: 知覚空間と作用空間で世界を認識する | E21: 5章 | F21: 見える範囲と攻撃できる範囲を分ける。 | G21: CanSeeで視野・距離・遮蔽、CanFireで銃口の射線と武器射程を別に判定する。 | H21: 頭が見えても射線が塞がる場合は射撃せず位置を変える。 | I21: 低い壁で視認可・発砲不可になる試験。 | J21: 分類・章番号は元シートを維持。
A22: 採用 | B22: 補助 | C22: 認識を作る | D22: 不確かな情報の信頼度を使って思考する | E22: 6章 | F22: 古い記憶や伝聞を現在の事実と混同しない。 | G22: 直接視認は信頼度1、記憶は3秒で減衰。報告は0.65を上限に1.5秒で減衰し、元の観測時刻を保持。0.2未満は捜索に使わず、高い信頼度の地点を優先する。 | H22: 見失った相手を透視追跡せず、記録した地点を短時間調べる。 | I22: 遮蔽中に相手を動かしても記憶位置が変わらないことと期限切れを検証。 | J22: 記憶・伝聞だけの射撃は禁止。
A23: 採用 | B23: 補助 | C23: 身体を作る | D23: キャラクターのセンサーを作る | E23: 7章 | F23: 敵味方の視界に入っているかを判断する。 | G23: VisionSensorで視野角と距離を絞り、胴・肩・頭へのLinecastで遮蔽を確認。約0.12秒間隔で更新する。 | H23: 背後・遠距離・完全に隠れた相手を認識しない。 | I23: 正面・背後・範囲外・完全遮蔽・頭だけ露出の試験。 | J23: 遮蔽物はWallレイヤー。タカULTの壁視認は明示的な例外。
A24: 採用 | B24: 補助 | C24: 身体を作る | D24: キャラクターの身体を認識するということ | E24: 7章 | F24: 自分の武器・身体・資源の制約を判断に使う。 | G24: キャラ別の射程・適正距離、HP、弾数、装填、ライデンゲージ、能力の再使用時間を参照する。 | H24: 届かない攻撃や条件を満たさない能力を連発しない。 | I24: 射程外・装填中・ゲージ不足と、既存の能力検証を組み合わせる。 | J24: 学習値ではなく現在の身体状態を使用。
A25: 未使用 | B25: 参考 | C25: 身体を作る | D25: 身体と知能 | E25: 7章
A26: 未使用 | B26: 参考 | C26: 身体を作る | D26: ゲームとアフォーダンス | E26: 7章
A27: 採用 | B27: 補助 | C27: 身体を作る | D27: 運動の統合 | E27: 7章 | F27: 経路移動と局所回避を両立する。 | G27: 実マップのColliderからNavMeshを生成。PathMotorの経路にセル近傍の分離操舵を合成し、CharacterControllerで移動する。 | H27: 遮蔽物を迂回し、仲間や敵同士の密集を緩和する。 | I27: 遮蔽物を挟んだ完全経路と、近接した2体が離れる方向を検証。 | J27: 氷壁はNavMeshObstacleのcarvingで反映。
A28: 未使用 | B28: 参考 | C28: 身体を作る | D28: 協応の原理 | E28: 7章
A29: 未使用 | B29: 参考 | C29: 身体を作る | D29: 環境にキャラクターを操作させる | E29: 7章
A30: 未使用 | B30: 参考 | C30: 身体を作る | D30: キャラクターの生活感を出す | E30: 9章
A31: 未使用 | B31: 参考 | C31: 学習を作る | D31: ニューラルネットワーク入門 | E31: 6章
A32: 未使用 | B32: 参考 | C32: 学習を作る | D32: 学習・適応・進化 | E32: 6章
A33: 未使用 | B33: 参考 | C33: 学習を作る | D33: キャラクターが学習していく仕組み | E33: 5章
A34: 未使用 | B34: 参考 | C34: 協調を作る | D34: これからのゲームAI | E34: 9章
A35: 未使用 | B35: 参考 | C35: 協調を作る | D35: 街を作る | E35: 8章
A36: 未使用 | B36: 参考 | C36: 協調を作る | D36: 複数の思考による投票システム | E36: 8章
A37: 採用 | B37: 主 | C37: 協調を作る | D37: チーム表現 | E37: 8章 | F37: 部隊として命令と配置を表す。 | G37: SquadOrderを大命令、SquadBrainの状態を下位行動とする。追従の編隊位置と防衛範囲を個体へ割り当てる。 | H37: 同じ指示を共有しつつ、全員が同じ一点に集まらない。 | I37: 追従・防衛・攻撃を切り替え、状態と目的地をF1・ログで確認。 | J37: 個体の認識は独立。命令と味方の隊列情報は共有。
A38: 未使用 | B38: 参考 | C38: 協調を作る | D38: 群衆をたくさん作るためのLOD | E38: 8章
A39: 採用 | B39: 主 | C39: 協調を作る | D39: プレイヤーを包囲する方法 | E39: 8章 | F39: 近接する敵が同一点へ殺到するのを抑える。 | G39: SquadBlackboardで目標ごとの包囲スロットを予約。相手には8、タワーには12の候補位置を設け、期限付きで担当する。 | H39: 複数の敵が別方向から接近し、タワーの周囲へ展開する。 | I39: 同じ条件の2体に異なるスロットと間隔が与えられることを検証。 | J39: 包囲に使う相手位置は目視した観測位置のみ。
A40: 採用 | B40: 主 | C40: 協調を作る | D40: セルベースの群衆制御法 | E40: 8章 | F40: 近くの個体の密集と押し合いを減らす。 | G40: CrowdGridで2.5mセルへ個体を分け、周辺セルの物理的な近傍だけから分離方向を算出する。壁を挟む相手は回避計算から除外する。 | H40: 列や団子への過度な集中を緩和し、通路では自然に列になる。 | I40: 同一セルへ複数体を置き、間隔・回避方向と実際の群衆移動を確認。 | J40: 本作ではセル空間分割と局所密度回避として採用。
A41: 未使用 | B41: 参考 | C41: 協調を作る | D41: ソーシャル・ネットワーク・グラフ | E41: 6章
A42: 採用 | B42: 主 | C42: 協調を作る | D42: AI同士の連携 | E42: 5章 | F42: 味方の発見と攻撃担当を連携させる。 | G42: 目視したContactだけを報告し、担当予約数を目標の効用評価へ反映。報告を受けた味方は地点へ向かい、自分で再発見して攻撃する。 | H42: 離れた味方の発見を捜索に使い、過剰な集中攻撃を抑える。 | I42: 報告の元時刻・失効と、伝聞を新しい目視として再送しないことを検証。 | J42: 報告は射撃許可を与えない。
...

Sheet 03_提出用まとめ
A1: ゲームAI課題制作 提出用まとめ
A3: 「02_技術選択」で採用した項目を数式で自動表示します（22項目まで）。VBAの実行は不要です。
A5: 氏名 | B5: ='01_設計書'!B6 -> かも | C5: 学籍番号 | D5: ='01_設計書'!D6 -> 0 | E5: 作品名 | F5: ='01_設計書'!F6 -> WINGS
A6: 主分野 | B6: ='01_設計書'!H6 -> 協調を作る | C6: 補助1 | D6: ='01_設計書'!B7 -> 認識を作る | E6: 補助2 | F6: ='01_設計書'!D7 -> 身体を作る
A8: 採用した技術・概念
A9: 分野 | B9: 技術・概念 | C9: 章 | D9: 目的 | E9: Unity実装 | F9: 期待する挙動 | G9: 確認方法
A10: {=IFERROR(INDEX('02_技術選択'!$C$6:$I$56,_xlfn.AGGREGATE(15,6,(ROW('02_技術選択'!$A$6:$A$56)-ROW('02_技術選択'!$A$6)+1)/('02_技術選択'!$A$6:$A$56="採用"),ROWS($A$10:A10)),1),"")} -> 認識を作る | B10: {=IFERROR(INDEX('02_技術選択'!$C$6:$I$56,_xlfn.AGGREGATE(15,6,(ROW('02_技術選択'!$A$6:$A$56)-ROW('02_技術選択'!$A$6)+1)/('02_技術選択'!$A$6:$A$56="採用"),ROWS($A$10:A10)),2),"")} -> ブラックボード・アーキテクチャで世界を認識する | C10: {=IFERROR(INDEX('02_技術選択'!$C$6:$I$56,_xlfn.AGGREGATE(15,6,(ROW('02_技術選択'!$A$6:$A$56)-ROW('02_技術選択'!$A$6)+1)/('02_技術選択'!$A$6:$A$56="採用"),ROWS($A$10:A10)),3),"")} -> 2章 | D10: {=IFERROR(INDEX('02_技術選択'!$C$6:$I$56,_xlfn.AGGREGATE(15,6,(ROW('02_技術選択'!$A$6:$A$56)-ROW('02_技術選択'!$A$6)+1)/('02_技術選択'!$A$6:$A$56="採用"),ROWS($A$10:A10)),4),"")} -> センサーで得た事実を判断用の記録へ分離する。 | E10: {=IFERROR(INDEX('02_技術選択'!$C$6:$I$56,_xlfn.AGGREGATE(15,6,(ROW('02_技術選択'!$A$6:$A$56)-ROW('02_技術選択'!$A$6)+1)/('02_技術選択'!$A$6:$A$56="採用"),ROWS($A$10:A10)),5),"")} -> VisionSensorのContactに目標ID、観測位置、目撃時刻、可視状態、情報源、信頼度を保存する。 | F10: {=IFERROR(INDEX('02_技術選択'!$C$6:$I$56,_xlfn.AGGREGATE(15,6,(ROW('02_技術選択'!$A$6:$A$56)-ROW('02_技術選択'!$A$6)+1)/('02_技術選択'!$A$6:$A$56="採用"),ROWS($A$10:A10)),6),"")} -> 全体に存在する敵と、自分が知る敵を区別する。 | G10: {=IFERROR(INDEX('02_技術選択'!$C$6:$I$56,_xlfn.AGGREGATE(15,6,(ROW('02_技術選択'!$A$6:$A$56)-ROW('02_技術選択'!$A$6)+1)/('02_技術選択'!$A$6:$A$56="採用"),ROWS($A$10:A10)),7),"")} -> 背後・壁裏にいる登録済みの敵を選ばない試験。
A11: {=IFERROR(INDEX('02_技術選択'!$C$6:$I$56,_xlfn.AGGREGATE(15,6,(ROW('02_技術選択'!$A$6:$A$56)-ROW('02_技術選択'!$A$6)+1)/('02_技術選択'!$A$6:$A$56="採用"),ROWS($A$10:A11)),1),"")} -> 認識を作る | B11: {=IFERROR(INDEX('02_技術選択'!$C$6:$I$56,_xlfn.AGGREGATE(15,6,(ROW('02_技術選択'!$A$6:$A$56)-ROW('02_技術選択'!$A$6)+1)/('02_技術選択'!$A$6:$A$56="採用"),ROWS($A$10:A11)),2),"")} -> 知覚空間と作用空間で世界を認識する | C11: {=IFERROR(INDEX('02_技術選択'!$C$6:$I$56,_xlfn.AGGREGATE(15,6,(ROW('02_技術選択'!$A$6:$A$56)-ROW('02_技術選択'!$A$6)+1)/('02_技術選択'!$A$6:$A$56="採用"),ROWS($A$10:A11)),3),"")} -> 5章 | D11: {=IFERROR(INDEX('02_技術選択'!$C$6:$I$56,_xlfn.AGGREGATE(15,6,(ROW('02_技術選択'!$A$6:$A$56)-ROW('02_技術選択'!$A$6)+1)/('02_技術選択'!$A$6:$A$56="採用"),ROWS($A$10:A11)),4),"")} -> 見える範囲と攻撃できる範囲を分ける。 | E11: {=IFERROR(INDEX('02_技術選択'!$C$6:$I$56,_xlfn.AGGREGATE(15,6,(ROW('02_技術選択'!$A$6:$A$56)-ROW('02_技術選択'!$A$6)+1)/('02_技術選択'!$A$6:$A$56="採用"),ROWS($A$10:A11)),5),"")} -> CanSeeで視野・距離・遮蔽、CanFireで銃口の射線と武器射程を別に判定する。 | F11: {=IFERROR(INDEX('02_技術選択'!$C$6:$I$56,_xlfn.AGGREGATE(15,6,(ROW('02_技術選択'!$A$6:$A$56)-ROW('02_技術選択'!$A$6)+1)/('02_技術選択'!$A$6:$A$56="採用"),ROWS($A$10:A11)),6),"")} -> 頭が見えても射線が塞がる場合は射撃せず位置を変える。 | G11: {=IFERROR(INDEX('02_技術選択'!$C$6:$I$56,_xlfn.AGGREGATE(15,6,(ROW('02_技術選択'!$A$6:$A$56)-ROW('02_技術選択'!$A$6)+1)/('02_技術選択'!$A$6:$A$56="採用"),ROWS($A$10:A11)),7),"")} -> 低い壁で視認可・発砲不可になる試験。
A12: {=IFERROR(INDEX('02_技術選択'!$C$6:$I$56,_xlfn.AGGREGATE(15,6,(ROW('02_技術選択'!$A$6:$A$56)-ROW('02_技術選択'!$A$6)+1)/('02_技術選択'!$A$6:$A$56="採用"),ROWS($A$10:A12)),1),"")} -> 認識を作る | B12: {=IFERROR(INDEX('02_技術選択'!$C$6:$I$56,_xlfn.AGGREGATE(15,6,(ROW('02_技術選択'!$A$6:$A$56)-ROW('02_技術選択'!$A$6)+1)/('02_技術選択'!$A$6:$A$56="採用"),ROWS($A$10:A12)),2),"")} -> 不確かな情報の信頼度を使って思考する | C12: {=IFERROR(INDEX('02_技術選択'!$C$6:$I$56,_xlfn.AGGREGATE(15,6,(ROW('02_技術選択'!$A$6:$A$56)-ROW('02_技術選択'!$A$6)+1)/('02_技術選択'!$A$6:$A$56="採用"),ROWS($A$10:A12)),3),"")} -> 6章 | D12: {=IFERROR(INDEX('02_技術選択'!$C$6:$I$56,_xlfn.AGGREGATE(15,6,(ROW('02_技術選択'!$A$6:$A$56)-ROW('02_技術選択'!$A$6)+1)/('02_技術選択'!$A$6:$A$56="採用"),ROWS($A$10:A12)),4),"")} -> 古い記憶や伝聞を現在の事実と混同しない。 | E12: {=IFERROR(INDEX('02_技術選択'!$C$6:$I$56,_xlfn.AGGREGATE(15,6,(ROW('02_技術選択'!$A$6:$A$56)-ROW('02_技術選択'!$A$6)+1)/('02_技術選択'!$A$6:$A$56="採用"),ROWS($A$10:A12)),5),"")} -> 直接視認は信頼度1、記憶は3秒で減衰。報告は0.65を上限に1.5秒で減衰し、元の観測時刻を保持。0.2未満は捜索に使わず、高い信頼度の地点を優先する。 | F12: {=IFERROR(INDEX('02_技術選択'!$C$6:$I$56,_xlfn.AGGREGATE(15,6,(ROW('02_技術選択'!$A$6:$A$56)-ROW('02_技術選択'!$A$6)+1)/('02_技術選択'!$A$6:$A$56="採用"),ROWS($A$10:A12)),6),"")} -> 見失った相手を透視追跡せず、記録した地点を短時間調べる。 | G12: {=IFERROR(INDEX('02_技術選択'!$C$6:$I$56,_xlfn.AGGREGATE(15,6,(ROW('02_技術選択'!$A$6:$A$56)-ROW('02_技術選択'!$A$6)+1)/('02_技術選択'!$A$6:$A$56="採用"),ROWS($A$10:A12)),7),"")} -> 遮蔽中に相手を動かしても記憶位置が変わらないことと期限切れを検証。
A13: {=IFERROR(INDEX('02_技術選択'!$C$6:$I$56,_xlfn.AGGREGATE(15,6,(ROW('02_技術選択'!$A$6:$A$56)-ROW('02_技術選択'!$A$6)+1)/('02_技術選択'!$A$6:$A$56="採用"),ROWS($A$10:A13)),1),"")} -> 身体を作る | B13: {=IFERROR(INDEX('02_技術選択'!$C$6:$I$56,_xlfn.AGGREGATE(15,6,(ROW('02_技術選択'!$A$6:$A$56)-ROW('02_技術選択'!$A$6)+1)/('02_技術選択'!$A$6:$A$56="採用"),ROWS($A$10:A13)),2),"")} -> キャラクターのセンサーを作る | C13: {=IFERROR(INDEX('02_技術選択'!$C$6:$I$56,_xlfn.AGGREGATE(15,6,(ROW('02_技術選択'!$A$6:$A$56)-ROW('02_技術選択'!$A$6)+1)/('02_技術選択'!$A$6:$A$56="採用"),ROWS($A$10:A13)),3),"")} -> 7章 | D13: {=IFERROR(INDEX('02_技術選択'!$C$6:$I$56,_xlfn.AGGREGATE(15,6,(ROW('02_技術選択'!$A$6:$A$56)-ROW('02_技術選択'!$A$6)+1)/('02_技術選択'!$A$6:$A$56="採用"),ROWS($A$10:A13)),4),"")} -> 敵味方の視界に入っているかを判断する。 | E13: {=IFERROR(INDEX('02_技術選択'!$C$6:$I$56,_xlfn.AGGREGATE(15,6,(ROW('02_技術選択'!$A$6:$A$56)-ROW('02_技術選択'!$A$6)+1)/('02_技術選択'!$A$6:$A$56="採用"),ROWS($A$10:A13)),5),"")} -> VisionSensorで視野角と距離を絞り、胴・肩・頭へのLinecastで遮蔽を確認。約0.12秒間隔で更新する。 | F13: {=IFERROR(INDEX('02_技術選択'!$C$6:$I$56,_xlfn.AGGREGATE(15,6,(ROW('02_技術選択'!$A$6:$A$56)-ROW('02_技術選択'!$A$6)+1)/('02_技術選択'!$A$6:$A$56="採用"),ROWS($A$10:A13)),6),"")} -> 背後・遠距離・完全に隠れた相手を認識しない。 | G13: {=IFERROR(INDEX('02_技術選択'!$C$6:$I$56,_xlfn.AGGREGATE(15,6,(ROW('02_技術選択'!$A$6:$A$56)-ROW('02_技術選択'!$A$6)+1)/('02_技術選択'!$A$6:$A$56="採用"),ROWS($A$10:A13)),7),"")} -> 正面・背後・範囲外・完全遮蔽・頭だけ露出の試験。
A14: {=IFERROR(INDEX('02_技術選択'!$C$6:$I$56,_xlfn.AGGREGATE(15,6,(ROW('02_技術選択'!$A$6:$A$56)-ROW('02_技術選択'!$A$6)+1)/('02_技術選択'!$A$6:$A$56="採用"),ROWS($A$10:A14)),1),"")} -> 身体を作る | B14: {=IFERROR(INDEX('02_技術選択'!$C$6:$I$56,_xlfn.AGGREGATE(15,6,(ROW('02_技術選択'!$A$6:$A$56)-ROW('02_技術選択'!$A$6)+1)/('02_技術選択'!$A$6:$A$56="採用"),ROWS($A$10:A14)),2),"")} -> キャラクターの身体を認識するということ | C14: {=IFERROR(INDEX('02_技術選択'!$C$6:$I$56,_xlfn.AGGREGATE(15,6,(ROW('02_技術選択'!$A$6:$A$56)-ROW('02_技術選択'!$A$6)+1)/('02_技術選択'!$A$6:$A$56="採用"),ROWS($A$10:A14)),3),"")} -> 7章 | D14: {=IFERROR(INDEX('02_技術選択'!$C$6:$I$56,_xlfn.AGGREGATE(15,6,(ROW('02_技術選択'!$A$6:$A$56)-ROW('02_技術選択'!$A$6)+1)/('02_技術選択'!$A$6:$A$56="採用"),ROWS($A$10:A14)),4),"")} -> 自分の武器・身体・資源の制約を判断に使う。 | E14: {=IFERROR(INDEX('02_技術選択'!$C$6:$I$56,_xlfn.AGGREGATE(15,6,(ROW('02_技術選択'!$A$6:$A$56)-ROW('02_技術選択'!$A$6)+1)/('02_技術選択'!$A$6:$A$56="採用"),ROWS($A$10:A14)),5),"")} -> キャラ別の射程・適正距離、HP、弾数、装填、ライデンゲージ、能力の再使用時間を参照する。 | F14: {=IFERROR(INDEX('02_技術選択'!$C$6:$I$56,_xlfn.AGGREGATE(15,6,(ROW('02_技術選択'!$A$6:$A$56)-ROW('02_技術選択'!$A$6)+1)/('02_技術選択'!$A$6:$A$56="採用"),ROWS($A$10:A14)),6),"")} -> 届かない攻撃や条件を満たさない能力を連発しない。 | G14: {=IFERROR(INDEX('02_技術選択'!$C$6:$I$56,_xlfn.AGGREGATE(15,6,(ROW('02_技術選択'!$A$6:$A$56)-ROW('02_技術選択'!$A$6)+1)/('02_技術選択'!$A$6:$A$56="採用"),ROWS($A$10:A14)),7),"")} -> 射程外・装填中・ゲージ不足と、既存の能力検証を組み合わせる。
A15: {=IFERROR(INDEX('02_技術選択'!$C$6:$I$56,_xlfn.AGGREGATE(15,6,(ROW('02_技術選択'!$A$6:$A$56)-ROW('02_技術選択'!$A$6)+1)/('02_技術選択'!$A$6:$A$56="採用"),ROWS($A$10:A15)),1),"")} -> 身体を作る | B15: {=IFERROR(INDEX('02_技術選択'!$C$6:$I$56,_xlfn.AGGREGATE(15,6,(ROW('02_技術選択'!$A$6:$A$56)-ROW('02_技術選択'!$A$6)+1)/('02_技術選択'!$A$6:$A$56="採用"),ROWS($A$10:A15)),2),"")} -> 運動の統合 | C15: {=IFERROR(INDEX('02_技術選択'!$C$6:$I$56,_xlfn.AGGREGATE(15,6,(ROW('02_技術選択'!$A$6:$A$56)-ROW('02_技術選択'!$A$6)+1)/('02_技術選択'!$A$6:$A$56="採用"),ROWS($A$10:A15)),3),"")} -> 7章 | D15: {=IFERROR(INDEX('02_技術選択'!$C$6:$I$56,_xlfn.AGGREGATE(15,6,(ROW('02_技術選択'!$A$6:$A$56)-ROW('02_技術選択'!$A$6)+1)/('02_技術選択'!$A$6:$A$56="採用"),ROWS($A$10:A15)),4),"")} -> 経路移動と局所回避を両立する。 | E15: {=IFERROR(INDEX('02_技術選択'!$C$6:$I$56,_xlfn.AGGREGATE(15,6,(ROW('02_技術選択'!$A$6:$A$56)-ROW('02_技術選択'!$A$6)+1)/('02_技術選択'!$A$6:$A$56="採用"),ROWS($A$10:A15)),5),"")} -> 実マップのColliderからNavMeshを生成。PathMotorの経路にセル近傍の分離操舵を合成し、CharacterControllerで移動する。 | F15: {=IFERROR(INDEX('02_技術選択'!$C$6:$I$56,_xlfn.AGGREGATE(15,6,(ROW('02_技術選択'!$A$6:$A$56)-ROW('02_技術選択'!$A$6)+1)/('02_技術選択'!$A$6:$A$56="採用"),ROWS($A$10:A15)),6),"")} -> 遮蔽物を迂回し、仲間や敵同士の密集を緩和する。 | G15: {=IFERROR(INDEX('02_技術選択'!$C$6:$I$56,_xlfn.AGGREGATE(15,6,(ROW('02_技術選択'!$A$6:$A$56)-ROW('02_技術選択'!$A$6)+1)/('02_技術選択'!$A$6:$A$56="採用"),ROWS($A$10:A15)),7),"")} -> 遮蔽物を挟んだ完全経路と、近接した2体が離れる方向を検証。
A16: {=IFERROR(INDEX('02_技術選択'!$C$6:$I$56,_xlfn.AGGREGATE(15,6,(ROW('02_技術選択'!$A$6:$A$56)-ROW('02_技術選択'!$A$6)+1)/('02_技術選択'!$A$6:$A$56="採用"),ROWS($A$10:A16)),1),"")} -> 協調を作る | B16: {=IFERROR(INDEX('02_技術選択'!$C$6:$I$56,_xlfn.AGGREGATE(15,6,(ROW('02_技術選択'!$A$6:$A$56)-ROW('02_技術選択'!$A$6)+1)/('02_技術選択'!$A$6:$A$56="採用"),ROWS($A$10:A16)),2),"")} -> チーム表現 | C16: {=IFERROR(INDEX('02_技術選択'!$C$6:$I$56,_xlfn.AGGREGATE(15,6,(ROW('02_技術選択'!$A$6:$A$56)-ROW('02_技術選択'!$A$6)+1)/('02_技術選択'!$A$6:$A$56="採用"),ROWS($A$10:A16)),3),"")} -> 8章 | D16: {=IFERROR(INDEX('02_技術選択'!$C$6:$I$56,_xlfn.AGGREGATE(15,6,(ROW('02_技術選択'!$A$6:$A$56)-ROW('02_技術選択'!$A$6)+1)/('02_技術選択'!$A$6:$A$56="採用"),ROWS($A$10:A16)),4),"")} -> 部隊として命令と配置を表す。 | E16: {=IFERROR(INDEX('02_技術選択'!$C$6:$I$56,_xlfn.AGGREGATE(15,6,(ROW('02_技術選択'!$A$6:$A$56)-ROW('02_技術選択'!$A$6)+1)/('02_技術選択'!$A$6:$A$56="採用"),ROWS($A$10:A16)),5),"")} -> SquadOrderを大命令、SquadBrainの状態を下位行動とする。追従の編隊位置と防衛範囲を個体へ割り当てる。 | F16: {=IFERROR(INDEX('02_技術選択'!$C$6:$I$56,_xlfn.AGGREGATE(15,6,(ROW('02_技術選択'!$A$6:$A$56)-ROW('02_技術選択'!$A$6)+1)/('02_技術選択'!$A$6:$A$56="採用"),ROWS($A$10:A16)),6),"")} -> 同じ指示を共有しつつ、全員が同じ一点に集まらない。 | G16: {=IFERROR(INDEX('02_技術選択'!$C$6:$I$56,_xlfn.AGGREGATE(15,6,(ROW('02_技術選択'!$A$6:$A$56)-ROW('02_技術選択'!$A$6)+1)/('02_技術選択'!$A$6:$A$56="採用"),ROWS($A$10:A16)),7),"")} -> 追従・防衛・攻撃を切り替え、状態と目的地をF1・ログで確認。
A17: {=IFERROR(INDEX('02_技術選択'!$C$6:$I$56,_xlfn.AGGREGATE(15,6,(ROW('02_技術選択'!$A$6:$A$56)-ROW('02_技術選択'!$A$6)+1)/('02_技術選択'!$A$6:$A$56="採用"),ROWS($A$10:A17)),1),"")} -> 協調を作る | B17: {=IFERROR(INDEX('02_技術選択'!$C$6:$I$56,_xlfn.AGGREGATE(15,6,(ROW('02_技術選択'!$A$6:$A$56)-ROW('02_技術選択'!$A$6)+1)/('02_技術選択'!$A$6:$A$56="採用"),ROWS($A$10:A17)),2),"")} -> プレイヤーを包囲する方法 | C17: {=IFERROR(INDEX('02_技術選択'!$C$6:$I$56,_xlfn.AGGREGATE(15,6,(ROW('02_技術選択'!$A$6:$A$56)-ROW('02_技術選択'!$A$6)+1)/('02_技術選択'!$A$6:$A$56="採用"),ROWS($A$10:A17)),3),"")} -> 8章 | D17: {=IFERROR(INDEX('02_技術選択'!$C$6:$I$56,_xlfn.AGGREGATE(15,6,(ROW('02_技術選択'!$A$6:$A$56)-ROW('02_技術選択'!$A$6)+1)/('02_技術選択'!$A$6:$A$56="採用"),ROWS($A$10:A17)),4),"")} -> 近接する敵が同一点へ殺到するのを抑える。 | E17: {=IFERROR(INDEX('02_技術選択'!$C$6:$I$56,_xlfn.AGGREGATE(15,6,(ROW('02_技術選択'!$A$6:$A$56)-ROW('02_技術選択'!$A$6)+1)/('02_技術選択'!$A$6:$A$56="採用"),ROWS($A$10:A17)),5),"")} -> SquadBlackboardで目標ごとの包囲スロットを予約。相手には8、タワーには12の候補位置を設け、期限付きで担当する。 | F17: {=IFERROR(INDEX('02_技術選択'!$C$6:$I$56,_xlfn.AGGREGATE(15,6,(ROW('02_技術選択'!$A$6:$A$56)-ROW('02_技術選択'!$A$6)+1)/('02_技術選択'!$A$6:$A$56="採用"),ROWS($A$10:A17)),6),"")} -> 複数の敵が別方向から接近し、タワーの周囲へ展開する。 | G17: {=IFERROR(INDEX('02_技術選択'!$C$6:$I$56,_xlfn.AGGREGATE(15,6,(ROW('02_技術選択'!$A$6:$A$56)-ROW('02_技術選択'!$A$6)+1)/('02_技術選択'!$A$6:$A$56="採用"),ROWS($A$10:A17)),7),"")} -> 同じ条件の2体に異なるスロットと間隔が与えられることを検証。
A18: {=IFERROR(INDEX('02_技術選択'!$C$6:$I$56,_xlfn.AGGREGATE(15,6,(ROW('02_技術選択'!$A$6:$A$56)-ROW('02_技術選択'!$A$6)+1)/('02_技術選択'!$A$6:$A$56="採用"),ROWS($A$10:A18)),1),"")} -> 協調を作る | B18: {=IFERROR(INDEX('02_技術選択'!$C$6:$I$56,_xlfn.AGGREGATE(15,6,(ROW('02_技術選択'!$A$6:$A$56)-ROW('02_技術選択'!$A$6)+1)/('02_技術選択'!$A$6:$A$56="採用"),ROWS($A$10:A18)),2),"")} -> セルベースの群衆制御法 | C18: {=IFERROR(INDEX('02_技術選択'!$C$6:$I$56,_xlfn.AGGREGATE(15,6,(ROW('02_技術選択'!$A$6:$A$56)-ROW('02_技術選択'!$A$6)+1)/('02_技術選択'!$A$6:$A$56="採用"),ROWS($A$10:A18)),3),"")} -> 8章 | D18: {=IFERROR(INDEX('02_技術選択'!$C$6:$I$56,_xlfn.AGGREGATE(15,6,(ROW('02_技術選択'!$A$6:$A$56)-ROW('02_技術選択'!$A$6)+1)/('02_技術選択'!$A$6:$A$56="採用"),ROWS($A$10:A18)),4),"")} -> 近くの個体の密集と押し合いを減らす。 | E18: {=IFERROR(INDEX('02_技術選択'!$C$6:$I$56,_xlfn.AGGREGATE(15,6,(ROW('02_技術選択'!$A$6:$A$56)-ROW('02_技術選択'!$A$6)+1)/('02_技術選択'!$A$6:$A$56="採用"),ROWS($A$10:A18)),5),"")} -> CrowdGridで2.5mセルへ個体を分け、周辺セルの物理的な近傍だけから分離方向を算出する。壁を挟む相手は回避計算から除外する。 | F18: {=IFERROR(INDEX('02_技術選択'!$C$6:$I$56,_xlfn.AGGREGATE(15,6,(ROW('02_技術選択'!$A$6:$A$56)-ROW('02_技術選択'!$A$6)+1)/('02_技術選択'!$A$6:$A$56="採用"),ROWS($A$10:A18)),6),"")} -> 列や団子への過度な集中を緩和し、通路では自然に列になる。 | G18: {=IFERROR(INDEX('02_技術選択'!$C$6:$I$56,_xlfn.AGGREGATE(15,6,(ROW('02_技術選択'!$A$6:$A$56)-ROW('02_技術選択'!$A$6)+1)/('02_技術選択'!$A$6:$A$56="採用"),ROWS($A$10:A18)),7),"")} -> 同一セルへ複数体を置き、間隔・回避方向と実際の群衆移動を確認。
A19: {=IFERROR(INDEX('02_技術選択'!$C$6:$I$56,_xlfn.AGGREGATE(15,6,(ROW('02_技術選択'!$A$6:$A$56)-ROW('02_技術選択'!$A$6)+1)/('02_技術選択'!$A$6:$A$56="採用"),ROWS($A$10:A19)),1),"")} -> 協調を作る | B19: {=IFERROR(INDEX('02_技術選択'!$C$6:$I$56,_xlfn.AGGREGATE(15,6,(ROW('02_技術選択'!$A$6:$A$56)-ROW('02_技術選択'!$A$6)+1)/('02_技術選択'!$A$6:$A$56="採用"),ROWS($A$10:A19)),2),"")} -> AI同士の連携 | C19: {=IFERROR(INDEX('02_技術選択'!$C$6:$I$56,_xlfn.AGGREGATE(15,6,(ROW('02_技術選択'!$A$6:$A$56)-ROW('02_技術選択'!$A$6)+1)/('02_技術選択'!$A$6:$A$56="採用"),ROWS($A$10:A19)),3),"")} -> 5章 | D19: {=IFERROR(INDEX('02_技術選択'!$C$6:$I$56,_xlfn.AGGREGATE(15,6,(ROW('02_技術選択'!$A$6:$A$56)-ROW('02_技術選択'!$A$6)+1)/('02_技術選択'!$A$6:$A$56="採用"),ROWS($A$10:A19)),4),"")} -> 味方の発見と攻撃担当を連携させる。 | E19: {=IFERROR(INDEX('02_技術選択'!$C$6:$I$56,_xlfn.AGGREGATE(15,6,(ROW('02_技術選択'!$A$6:$A$56)-ROW('02_技術選択'!$A$6)+1)/('02_技術選択'!$A$6:$A$56="採用"),ROWS($A$10:A19)),5),"")} -> 目視したContactだけを報告し、担当予約数を目標の効用評価へ反映。報告を受けた味方は地点へ向かい、自分で再発見して攻撃する。 | F19: {=IFERROR(INDEX('02_技術選択'!$C$6:$I$56,_xlfn.AGGREGATE(15,6,(ROW('02_技術選択'!$A$6:$A$56)-ROW('02_技術選択'!$A$6)+1)/('02_技術選択'!$A$6:$A$56="採用"),ROWS($A$10:A19)),6),"")} -> 離れた味方の発見を捜索に使い、過剰な集中攻撃を抑える。 | G19: {=IFERROR(INDEX('02_技術選択'!$C$6:$I$56,_xlfn.AGGREGATE(15,6,(ROW('02_技術選択'!$A$6:$A$56)-ROW('02_技術選択'!$A$6)+1)/('02_技術選択'!$A$6:$A$56="採用"),ROWS($A$10:A19)),7),"")} -> 報告の元時刻・失効と、伝聞を新しい目視として再送しないことを検証。
A20: {=IFERROR(INDEX('02_技術選択'!$C$6:$I$56,_xlfn.AGGREGATE(15,6,(ROW('02_技術選択'!$A$6:$A$56)-ROW('02_技術選択'!$A$6)+1)/('02_技術選択'!$A$6:$A$56="採用"),ROWS($A$10:A20)),1),"")} -> 協調を作る | B20: {=IFERROR(INDEX('02_技術選択'!$C$6:$I$56,_xlfn.AGGREGATE(15,6,(ROW('02_技術選択'!$A$6:$A$56)-ROW('02_技術選択'!$A$6)+1)/('02_技術選択'!$A$6:$A$56="採用"),ROWS($A$10:A20)),2),"")} -> ブラックボードで情報を把握する | C20: {=IFERROR(INDEX('02_技術選択'!$C$6:$I$56,_xlfn.AGGREGATE(15,6,(ROW('02_技術選択'!$A$6:$A$56)-ROW('02_技術選択'!$A$6)+1)/('02_技術選択'!$A$6:$A$56="採用"),ROWS($A$10:A20)),3),"")} -> 2章 | D20: {=IFERROR(INDEX('02_技術選択'!$C$6:$I$56,_xlfn.AGGREGATE(15,6,(ROW('02_技術選択'!$A$6:$A$56)-ROW('02_技術選択'!$A$6)+1)/('02_技術選択'!$A$6:$A$56="採用"),ROWS($A$10:A20)),4),"")} -> 共有情報と配置予約を一か所で管理する。 | E20: {=IFERROR(INDEX('02_技術選択'!$C$6:$I$56,_xlfn.AGGREGATE(15,6,(ROW('02_技術選択'!$A$6:$A$56)-ROW('02_技術選択'!$A$6)+1)/('02_技術選択'!$A$6:$A$56="採用"),ROWS($A$10:A20)),5),"")} -> SquadBlackboardに観測位置・報告者・観測時刻と、担当スロット・予約期限を保持する。死亡・任務終了時に予約を解放する。 | F20: {=IFERROR(INDEX('02_技術選択'!$C$6:$I$56,_xlfn.AGGREGATE(15,6,(ROW('02_技術選択'!$A$6:$A$56)-ROW('02_技術選択'!$A$6)+1)/('02_技術選択'!$A$6:$A$56="採用"),ROWS($A$10:A20)),6),"")} -> 共有情報の鮮度と、誰がどこを担当するかを説明できる。 | G20: {=IFERROR(INDEX('02_技術選択'!$C$6:$I$56,_xlfn.AGGREGATE(15,6,(ROW('02_技術選択'!$A$6:$A$56)-ROW('02_技術選択'!$A$6)+1)/('02_技術選択'!$A$6:$A$56="採用"),ROWS($A$10:A20)),7),"")} -> 報告の失効、スロット競合の回避、任務終了時の初期化を確認。
A21: {=IFERROR(INDEX('02_技術選択'!$C$6:$I$56,_xlfn.AGGREGATE(15,6,(ROW('02_技術選択'!$A$6:$A$56)-ROW('02_技術選択'!$A$6)+1)/('02_技術選択'!$A$6:$A$56="採用"),ROWS($A$10:A21)),1),"")} -> 知能を作る | B21: {=IFERROR(INDEX('02_技術選択'!$C$6:$I$56,_xlfn.AGGREGATE(15,6,(ROW('02_技術選択'!$A$6:$A$56)-ROW('02_技術選択'!$A$6)+1)/('02_技術選択'!$A$6:$A$56="採用"),ROWS($A$10:A21)),2),"")} -> モジュラーデザインを作る | C21: {=IFERROR(INDEX('02_技術選択'!$C$6:$I$56,_xlfn.AGGREGATE(15,6,(ROW('02_技術選択'!$A$6:$A$56)-ROW('02_技術選択'!$A$6)+1)/('02_技術選択'!$A$6:$A$56="採用"),ROWS($A$10:A21)),3),"")} -> 3章 | D21: {=IFERROR(INDEX('02_技術選択'!$C$6:$I$56,_xlfn.AGGREGATE(15,6,(ROW('02_技術選択'!$A$6:$A$56)-ROW('02_技術選択'!$A$6)+1)/('02_技術選択'!$A$6:$A$56="採用"),ROWS($A$10:A21)),4),"")} -> 認識・判断・移動・行動を独立して改善できるようにする。 | E21: {=IFERROR(INDEX('02_技術選択'!$C$6:$I$56,_xlfn.AGGREGATE(15,6,(ROW('02_技術選択'!$A$6:$A$56)-ROW('02_技術選択'!$A$6)+1)/('02_技術選択'!$A$6:$A$56="採用"),ROWS($A$10:A21)),5),"")} -> AIBody、VisionSensor、SquadBrain/EnemyBrain、PathMotor、既存の武器・能力処理へ分離する。 | F21: {=IFERROR(INDEX('02_技術選択'!$C$6:$I$56,_xlfn.AGGREGATE(15,6,(ROW('02_技術選択'!$A$6:$A$56)-ROW('02_技術選択'!$A$6)+1)/('02_技術選択'!$A$6:$A$56="採用"),ROWS($A$10:A21)),6),"")} -> 認識ルールを変えても武器処理を作り直さずに済む。 | G21: {=IFERROR(INDEX('02_技術選択'!$C$6:$I$56,_xlfn.AGGREGATE(15,6,(ROW('02_技術選択'!$A$6:$A$56)-ROW('02_技術選択'!$A$6)+1)/('02_技術選択'!$A$6:$A$56="採用"),ROWS($A$10:A21)),7),"")} -> 認識だけの試験、命令の判断試験、実際の防衛戦を段階的に実行。
... A31: {=IFERROR(INDEX('02_技術選択'!$C$6:$I$56,_xlfn.AGGREGATE(15,6,(ROW('02_技術選択'!$A$6:$A$56)-ROW('02_技術選択'!$A$6)+1)/('02_技術選択'!$A$6:$A$56="採用"),ROWS($A$10:A31)),1),"")} | B31: {=IFERROR(INDEX('02_技術選択'!$C$6:$I$56,_xlfn.AGGREGATE(15,6,(ROW('02_技術選択'!$A$6:$A$56)-ROW('02_技術選択'!$A$6)+1)/('02_技術選択'!$A$6:$A$56="採用"),ROWS($A$10:A31)),2),"")} | C31: {=IFERROR(INDEX('02_技術選択'!$C$6:$I$56,_xlfn.AGGREGATE(15,6,(ROW('02_技術選択'!$A$6:$A$56)-ROW('02_技術選択'!$A$6)+1)/('02_技術選択'!$A$6:$A$56="採用"),ROWS($A$10:A31)),3),"")} | D31: {=IFERROR(INDEX('02_技術選択'!$C$6:$I$56,_xlfn.AGGREGATE(15,6,(ROW('02_技術選択'!$A$6:$A$56)-ROW('02_技術選択'!$A$6)+1)/('02_技術選択'!$A$6:$A$56="採用"),ROWS($A$10:A31)),4),"")} | E31: {=IFERROR(INDEX('02_技術選択'!$C$6:$I$56,_xlfn.AGGREGATE(15,6,(ROW('02_技術選択'!$A$6:$A$56)-ROW('02_技術選択'!$A$6)+1)/('02_技術選択'!$A$6:$A$56="採用"),ROWS($A$10:A31)),5),"")} | F31: {=IFERROR(INDEX('02_技術選択'!$C$6:$I$56,_xlfn.AGGREGATE(15,6,(ROW('02_技術選択'!$A$6:$A$56)-ROW('02_技術選択'!$A$6)+1)/('02_技術選択'!$A$6:$A$56="採用"),ROWS($A$10:A31)),6),"")} | G31: {=IFERROR(INDEX('02_技術選択'!$C$6:$I$56,_xlfn.AGGREGATE(15,6,(ROW('02_技術選択'!$A$6:$A$56)-ROW('02_技術選択'!$A$6)+1)/('02_技術選択'!$A$6:$A$56="採用"),ROWS($A$10:A31)),7),"")}
A32: AI全体の説明（設計書から転記）
A33: AIの目的 | B33: ='01_設計書'!B10 -> タワーへ侵攻する敵群と、追従・防衛・攻撃の指示を遂行する味方部隊を制御する。認識→判断→移動・攻撃を分離し、全体リストにいるだけの敵を既知とは扱わない。
A35: 見せたい知性 | B35: ='01_設計書'!D10 -> 敵はNavMeshで拠点へ進み、セル内の近傍回避と包囲位置の予約で一列への集中を抑える。味方は編隊間隔と命令の行動範囲を保ち、目視した敵から適した攻撃目標を選ぶ。見失った相手の現在位置は追わない。
A37: 認識するもの | B37: ='01_設計書'!F10 -> 視覚は距離・水平視野角・上下角・遮蔽物を約0.12秒ごとに判定。味方は120度、敵は110度。視認距離は味方25～55m、敵20～25m。胴・肩・頭の3点を調べ、射撃は別に銃口からの射線と武器射程を確認する。タワー位置とNavMeshは既知の任務・地図情報。音の推定は未採用。
A39: 内部状態・記憶 | B39: ='01_設計書'!H10 -> 大命令は追従・防衛・攻撃を保持。追従は編隊位置へ戻り、リーダーから12mを超えたら帰還を優先。防衛はタワーから11mの範囲を維持。攻撃は目視した敵へ接近し、敵を知らなければ巡回。内部状態は警戒・帰還・追跡・位置調整・攻撃・捜索・装填。最終目撃位置は固定して3秒で忘れ、味方の報告は元の目撃時刻から1.5秒で失効。HP・弾数・射程・クールダウンも参照する。
A41: 判断方法 | B41: ='01_設計書'!B13 -> 大命令＋FSMで行動を切り替え、目視した候補の距離・拠点への脅威・味方の担当数を効用スコアで比較する。目標は0.65秒保持し、原則8点以上有利な候補へ切替。安全条件はルールで判定。GOAP、学習、先読みシミュレーションは今回は使用しない。
A43: 行動 | B43: ='01_設計書'!D13 -> 敵：拠点へ進行、目視した相手へ接近・包囲、射線・距離確認後に攻撃。味方：編隊追従、拠点警戒、巡回、目視目標の追跡、適正射程への位置調整、装填、状況に応じた固有能力。視界を失うと最終目撃地点を調べる。
A45: 世界・身体の制約 | B45: ='01_設計書'!F13 -> 視界外の現在位置・HPは判断に使わない。記憶・報告だけでは射撃しない。頭が見えても銃口が隠れていれば位置を変える。タカのULTは壁の遮蔽だけ例外で、距離・視野角は維持。物理的な近傍回避は敵の発見情報にはしない。移動先は命令の範囲とNavMeshに制約される。
A47: 確認方法 | B47: ='01_設計書'!H13 -> F1で味方の命令・状態・判断理由・目視数・射撃許可・経路を表示。UnityでAIBodyを選択すると視野扇形、目視線、最終目撃地点をGizmos表示。味方の状態遷移はログに記録。自動検証で背後・距離外・遮蔽・低い壁・記憶の固定と失効・報告の失効・行動範囲・NavMesh迂回・包囲分担を確認する。

Sheet 04_使い方
A1: このシートの使い方
A4: 手順 | B4: すること | C4: ポイント
A5: 1 | B5: 01_設計書を書く | C5: AIの目的／認識／内部状態／判断／行動を先に言葉にする。
A6: 2 | B6: 主分野を1つ選ぶ | C6: 6分野のうち、自分の作品で最も掘り下げる分野を決める。
A7: 3 | B7: 02_技術選択で技術を選ぶ | C7: 最低でも主分野から1項目を「採用」。必要なら補助分野も使う。
A8: 4 | B8: 採用項目の実装方針を書く | C8: F～I列に「目的・Unity実装・期待する挙動・確認方法」を書く。
A9: 5 | B9: Unityで実装・検証する | C9: コードの完成だけでなく、判断理由が観察できるようにする。
A10: 6 | B10: 提出用まとめを更新する | C10: この改訂版では数式で自動反映。採用項目とF～I列の実装方針が一致することを確認する。
A12: 6分野の意味
A13: ゲームAIの作り方 | B13: ゲームAIをどう捉え、どんな体験を作るかという土台。 | D13: ・ | E13: AIの認識→判断→行動が説明できる
A14: 認識を作る | B14: AIが世界の何を、どのような形で知るか。 | D14: ・ | E14: 主分野と採用した技術・概念が明示されている
A15: 身体を作る | B15: センサー・身体状態・運動能力を通じて世界と関わる。 | D15: ・ | E15: 採用技術をUnity上でどう実装したか説明できる
A16: 学習を作る | B16: 経験や適応によって、将来の判断や内部状態が変化する。 | D16: ・ | E16: 状況が変わるとAIの振る舞いも変わる
A17: 協調を作る | B17: 複数AIが情報や役割を共有し、集団として振る舞う。 | D17: ・ | E17: 判断理由や内部状態を観察できる
A18: 知能を作る | B18: 自律性・モジュール構造・意思決定アルゴリズムを設計する。
A20: マクロについて
A21: この改訂版では .xlsx のまま使用できます。「03_提出用まとめ」は採用状況と実装方針に数式で連動するため、VBAマクロの導入・実行は不要です。採用後は、元の技術名・章番号を保ち、F～I列の説明と実際のコードを対応させてください。
